 * Serving Flask app 'run_app'
 * Debug mode: on
[31m[1mWARNING: This is a development server. Do not use it in a production deployment. Use a production WSGI server instead.[0m
 * Running on all addresses (0.0.0.0)
 * Running on http://127.0.0.1:5000
 * Running on http://172.25.21.92:5000
[33mPress CTRL+C to quit[0m
 * Restarting with stat
 * Debugger is active!
 * Debugger PIN: 995-271-986
 * Detected change in '/root/code/ai_based_education/test.py', reloading
 * Restarting with stat
 * Debugger is active!
 * Debugger PIN: 995-271-986
127.0.0.1 - - [29/Sep/2025 15:52:09] "POST /swot HTTP/1.1" 200 -
/root/code/ai_based_education/tools/load_talent_evidence.py:53: SettingWithCopyWarning: 
A value is trying to be set on a copy of a slice from a DataFrame.
Try using .loc[row_indexer,col_indexer] = value instead

See the caveats in the documentation: https://pandas.pydata.org/pandas-docs/stable/user_guide/indexing.html#returning-a-view-versus-a-copy
  target['ÂàÜÁ±ª'] = target['ÂàÜÁ±ª'].map(talent_insert)
/root/code/ai_based_education/tools/load_talent_evidence.py:53: SettingWithCopyWarning: 
A value is trying to be set on a copy of a slice from a DataFrame.
Try using .loc[row_indexer,col_indexer] = value instead

See the caveats in the documentation: https://pandas.pydata.org/pandas-docs/stable/user_guide/indexing.html#returning-a-view-versus-a-copy
  target['ÂàÜÁ±ª'] = target['ÂàÜÁ±ª'].map(talent_insert)
/root/code/ai_based_education/tools/load_talent_evidence.py:53: SettingWithCopyWarning: 
A value is trying to be set on a copy of a slice from a DataFrame.
Try using .loc[row_indexer,col_indexer] = value instead

See the caveats in the documentation: https://pandas.pydata.org/pandas-docs/stable/user_guide/indexing.html#returning-a-view-versus-a-copy
  target['ÂàÜÁ±ª'] = target['ÂàÜÁ±ª'].map(talent_insert)
/root/code/ai_based_education/tools/load_talent_evidence.py:53: SettingWithCopyWarning: 
A value is trying to be set on a copy of a slice from a DataFrame.
Try using .loc[row_indexer,col_indexer] = value instead

See the caveats in the documentation: https://pandas.pydata.org/pandas-docs/stable/user_guide/indexing.html#returning-a-view-versus-a-copy
  target['ÂàÜÁ±ª'] = target['ÂàÜÁ±ª'].map(talent_insert)
111.9.62.28 - - [29/Sep/2025 15:52:45] "[35m[1mPOST /instant_profile HTTP/1.1[0m" 500 -
Traceback (most recent call last):
  File "/usr/local/lib/python3.8/site-packages/flask/app.py", line 1498, in __call__
    return self.wsgi_app(environ, start_response)
  File "/usr/local/lib/python3.8/site-packages/flask/app.py", line 1476, in wsgi_app
    response = self.handle_exception(e)
  File "/usr/local/lib/python3.8/site-packages/flask/app.py", line 1473, in wsgi_app
    response = self.full_dispatch_request()
  File "/usr/local/lib/python3.8/site-packages/flask/app.py", line 882, in full_dispatch_request
    rv = self.handle_user_exception(e)
  File "/usr/local/lib/python3.8/site-packages/flask/app.py", line 880, in full_dispatch_request
    rv = self.dispatch_request()
  File "/usr/local/lib/python3.8/site-packages/flask/app.py", line 865, in dispatch_request
    return self.ensure_sync(self.view_functions[rule.endpoint])(**view_args)  # type: ignore[no-any-return]
  File "/root/code/ai_based_education/run_app.py", line 71, in produe_instant_profile
    res = get_profile(req)
  File "/root/code/ai_based_education/main.py", line 152, in get_profile
    eng_level, rate = rate_classify(req)
  File "/root/code/ai_based_education/compute_score.py", line 200, in rate_classify
    eng_final_score, eng_final_level = eng_level_classify(req)
  File "/root/code/ai_based_education/compute_score.py", line 277, in eng_level_classify
    expect_info = eng_expect_score.get(req['student_info']['school_type']).get(req['student_info']['current_grade'])
AttributeError: 'NoneType' object has no attribute 'get'
111.9.62.28 - - [29/Sep/2025 15:53:11] "[35m[1mPOST /growth_advice HTTP/1.1[0m" 500 -
Traceback (most recent call last):
  File "/usr/local/lib/python3.8/site-packages/flask/app.py", line 1498, in __call__
    return self.wsgi_app(environ, start_response)
  File "/usr/local/lib/python3.8/site-packages/flask/app.py", line 1476, in wsgi_app
    response = self.handle_exception(e)
  File "/usr/local/lib/python3.8/site-packages/flask/app.py", line 1473, in wsgi_app
    response = self.full_dispatch_request()
  File "/usr/local/lib/python3.8/site-packages/flask/app.py", line 882, in full_dispatch_request
    rv = self.handle_user_exception(e)
  File "/usr/local/lib/python3.8/site-packages/flask/app.py", line 880, in full_dispatch_request
    rv = self.dispatch_request()
  File "/usr/local/lib/python3.8/site-packages/flask/app.py", line 865, in dispatch_request
    return self.ensure_sync(self.view_functions[rule.endpoint])(**view_args)  # type: ignore[no-any-return]
  File "/root/code/ai_based_education/run_app.py", line 135, in produe_growth_advice
    res = get_report(req)
  File "/root/code/ai_based_education/gen_report_wo_db.py", line 80, in get_report
    target_plan = [item for item in TP_PLANNING if item['ÁîªÂÉè‰ª£Á†Å'] in basic_info['‰∫∫ÊâçÁîªÂÉèÁ±ªÂûã']][0]
IndexError: list index out of range
87.120.191.33 - - [29/Sep/2025 15:54:01] "[33mGET / HTTP/1.1[0m" 404 -
111.9.62.28 - - [29/Sep/2025 15:54:13] "[35m[1mPOST /growth_advice HTTP/1.1[0m" 500 -
Traceback (most recent call last):
  File "/usr/local/lib/python3.8/site-packages/flask/app.py", line 1498, in __call__
    return self.wsgi_app(environ, start_response)
  File "/usr/local/lib/python3.8/site-packages/flask/app.py", line 1476, in wsgi_app
    response = self.handle_exception(e)
  File "/usr/local/lib/python3.8/site-packages/flask/app.py", line 1473, in wsgi_app
    response = self.full_dispatch_request()
  File "/usr/local/lib/python3.8/site-packages/flask/app.py", line 882, in full_dispatch_request
    rv = self.handle_user_exception(e)
  File "/usr/local/lib/python3.8/site-packages/flask/app.py", line 880, in full_dispatch_request
    rv = self.dispatch_request()
  File "/usr/local/lib/python3.8/site-packages/flask/app.py", line 865, in dispatch_request
    return self.ensure_sync(self.view_functions[rule.endpoint])(**view_args)  # type: ignore[no-any-return]
  File "/root/code/ai_based_education/run_app.py", line 135, in produe_growth_advice
    res = get_report(req)
  File "/root/code/ai_based_education/gen_report_wo_db.py", line 80, in get_report
    target_plan = [item for item in TP_PLANNING if item['ÁîªÂÉè‰ª£Á†Å'] in basic_info['‰∫∫ÊâçÁîªÂÉèÁ±ªÂûã']][0]
IndexError: list index out of range
47.107.188.255 - - [29/Sep/2025 15:57:02] "POST /open_question HTTP/1.1" 200 -
47.107.188.255 - - [29/Sep/2025 15:57:52] "POST /open_question HTTP/1.1" 200 -
/root/code/ai_based_education/tools/load_talent_evidence.py:53: SettingWithCopyWarning: 
A value is trying to be set on a copy of a slice from a DataFrame.
Try using .loc[row_indexer,col_indexer] = value instead

See the caveats in the documentation: https://pandas.pydata.org/pandas-docs/stable/user_guide/indexing.html#returning-a-view-versus-a-copy
  target['ÂàÜÁ±ª'] = target['ÂàÜÁ±ª'].map(talent_insert)
/root/code/ai_based_education/tools/load_talent_evidence.py:53: SettingWithCopyWarning: 
A value is trying to be set on a copy of a slice from a DataFrame.
Try using .loc[row_indexer,col_indexer] = value instead

See the caveats in the documentation: https://pandas.pydata.org/pandas-docs/stable/user_guide/indexing.html#returning-a-view-versus-a-copy
  target['ÂàÜÁ±ª'] = target['ÂàÜÁ±ª'].map(talent_insert)
/root/code/ai_based_education/tools/load_talent_evidence.py:53: SettingWithCopyWarning: 
A value is trying to be set on a copy of a slice from a DataFrame.
Try using .loc[row_indexer,col_indexer] = value instead

See the caveats in the documentation: https://pandas.pydata.org/pandas-docs/stable/user_guide/indexing.html#returning-a-view-versus-a-copy
  target['ÂàÜÁ±ª'] = target['ÂàÜÁ±ª'].map(talent_insert)
/root/code/ai_based_education/tools/load_talent_evidence.py:53: SettingWithCopyWarning: 
A value is trying to be set on a copy of a slice from a DataFrame.
Try using .loc[row_indexer,col_indexer] = value instead

See the caveats in the documentation: https://pandas.pydata.org/pandas-docs/stable/user_guide/indexing.html#returning-a-view-versus-a-copy
  target['ÂàÜÁ±ª'] = target['ÂàÜÁ±ª'].map(talent_insert)
47.107.188.255 - - [29/Sep/2025 15:58:02] "POST /instant_profile HTTP/1.1" 200 -
47.107.188.255 - - [29/Sep/2025 15:58:11] "POST /growth_advice HTTP/1.1" 200 -
47.107.188.255 - - [29/Sep/2025 15:58:28] "POST /swot HTTP/1.1" 200 -
47.107.188.255 - - [29/Sep/2025 15:58:28] "[35m[1mPOST /growth_advice HTTP/1.1[0m" 500 -
Traceback (most recent call last):
  File "/usr/local/lib/python3.8/site-packages/flask/app.py", line 1498, in __call__
    return self.wsgi_app(environ, start_response)
  File "/usr/local/lib/python3.8/site-packages/flask/app.py", line 1476, in wsgi_app
    response = self.handle_exception(e)
  File "/usr/local/lib/python3.8/site-packages/flask/app.py", line 1473, in wsgi_app
    response = self.full_dispatch_request()
  File "/usr/local/lib/python3.8/site-packages/flask/app.py", line 882, in full_dispatch_request
    rv = self.handle_user_exception(e)
  File "/usr/local/lib/python3.8/site-packages/flask/app.py", line 880, in full_dispatch_request
    rv = self.dispatch_request()
  File "/usr/local/lib/python3.8/site-packages/flask/app.py", line 865, in dispatch_request
    return self.ensure_sync(self.view_functions[rule.endpoint])(**view_args)  # type: ignore[no-any-return]
  File "/root/code/ai_based_education/run_app.py", line 135, in produe_growth_advice
    res = get_report(req)
  File "/root/code/ai_based_education/gen_report_wo_db.py", line 84, in get_report
    target_plan.pop('AÊ°£ÂçáÂ≠¶‰∏ªÁ∫ø')
KeyError: 'AÊ°£ÂçáÂ≠¶‰∏ªÁ∫ø'
47.107.188.255 - - [29/Sep/2025 15:58:30] "[35m[1mPOST /growth_advice HTTP/1.1[0m" 500 -
Traceback (most recent call last):
  File "/usr/local/lib/python3.8/site-packages/flask/app.py", line 1498, in __call__
    return self.wsgi_app(environ, start_response)
  File "/usr/local/lib/python3.8/site-packages/flask/app.py", line 1476, in wsgi_app
    response = self.handle_exception(e)
  File "/usr/local/lib/python3.8/site-packages/flask/app.py", line 1473, in wsgi_app
    response = self.full_dispatch_request()
  File "/usr/local/lib/python3.8/site-packages/flask/app.py", line 882, in full_dispatch_request
    rv = self.handle_user_exception(e)
  File "/usr/local/lib/python3.8/site-packages/flask/app.py", line 880, in full_dispatch_request
    rv = self.dispatch_request()
  File "/usr/local/lib/python3.8/site-packages/flask/app.py", line 865, in dispatch_request
    return self.ensure_sync(self.view_functions[rule.endpoint])(**view_args)  # type: ignore[no-any-return]
  File "/root/code/ai_based_education/run_app.py", line 135, in produe_growth_advice
    res = get_report(req)
  File "/root/code/ai_based_education/gen_report_wo_db.py", line 84, in get_report
    target_plan.pop('AÊ°£ÂçáÂ≠¶‰∏ªÁ∫ø')
KeyError: 'AÊ°£ÂçáÂ≠¶‰∏ªÁ∫ø'
47.107.188.255 - - [29/Sep/2025 15:59:44] "[35m[1mPOST /growth_advice HTTP/1.1[0m" 500 -
Traceback (most recent call last):
  File "/usr/local/lib/python3.8/site-packages/flask/app.py", line 1498, in __call__
    return self.wsgi_app(environ, start_response)
  File "/usr/local/lib/python3.8/site-packages/flask/app.py", line 1476, in wsgi_app
    response = self.handle_exception(e)
  File "/usr/local/lib/python3.8/site-packages/flask/app.py", line 1473, in wsgi_app
    response = self.full_dispatch_request()
  File "/usr/local/lib/python3.8/site-packages/flask/app.py", line 882, in full_dispatch_request
    rv = self.handle_user_exception(e)
  File "/usr/local/lib/python3.8/site-packages/flask/app.py", line 880, in full_dispatch_request
    rv = self.dispatch_request()
  File "/usr/local/lib/python3.8/site-packages/flask/app.py", line 865, in dispatch_request
    return self.ensure_sync(self.view_functions[rule.endpoint])(**view_args)  # type: ignore[no-any-return]
  File "/root/code/ai_based_education/run_app.py", line 135, in produe_growth_advice
    res = get_report(req)
  File "/root/code/ai_based_education/gen_report_wo_db.py", line 84, in get_report
    target_plan.pop('AÊ°£ÂçáÂ≠¶‰∏ªÁ∫ø')
KeyError: 'AÊ°£ÂçáÂ≠¶‰∏ªÁ∫ø'
47.107.188.255 - - [29/Sep/2025 16:00:28] "[35m[1mPOST /growth_advice HTTP/1.1[0m" 500 -
Traceback (most recent call last):
  File "/usr/local/lib/python3.8/site-packages/flask/app.py", line 1498, in __call__
    return self.wsgi_app(environ, start_response)
  File "/usr/local/lib/python3.8/site-packages/flask/app.py", line 1476, in wsgi_app
    response = self.handle_exception(e)
  File "/usr/local/lib/python3.8/site-packages/flask/app.py", line 1473, in wsgi_app
    response = self.full_dispatch_request()
  File "/usr/local/lib/python3.8/site-packages/flask/app.py", line 882, in full_dispatch_request
    rv = self.handle_user_exception(e)
  File "/usr/local/lib/python3.8/site-packages/flask/app.py", line 880, in full_dispatch_request
    rv = self.dispatch_request()
  File "/usr/local/lib/python3.8/site-packages/flask/app.py", line 865, in dispatch_request
    return self.ensure_sync(self.view_functions[rule.endpoint])(**view_args)  # type: ignore[no-any-return]
  File "/root/code/ai_based_education/run_app.py", line 135, in produe_growth_advice
    res = get_report(req)
  File "/root/code/ai_based_education/gen_report_wo_db.py", line 84, in get_report
    target_plan.pop('AÊ°£ÂçáÂ≠¶‰∏ªÁ∫ø')
KeyError: 'AÊ°£ÂçáÂ≠¶‰∏ªÁ∫ø'
47.107.188.255 - - [29/Sep/2025 16:02:46] "[35m[1mPOST /growth_advice HTTP/1.1[0m" 500 -
Traceback (most recent call last):
  File "/usr/local/lib/python3.8/site-packages/flask/app.py", line 1498, in __call__
    return self.wsgi_app(environ, start_response)
  File "/usr/local/lib/python3.8/site-packages/flask/app.py", line 1476, in wsgi_app
    response = self.handle_exception(e)
  File "/usr/local/lib/python3.8/site-packages/flask/app.py", line 1473, in wsgi_app
    response = self.full_dispatch_request()
  File "/usr/local/lib/python3.8/site-packages/flask/app.py", line 882, in full_dispatch_request
    rv = self.handle_user_exception(e)
  File "/usr/local/lib/python3.8/site-packages/flask/app.py", line 880, in full_dispatch_request
    rv = self.dispatch_request()
  File "/usr/local/lib/python3.8/site-packages/flask/app.py", line 865, in dispatch_request
    return self.ensure_sync(self.view_functions[rule.endpoint])(**view_args)  # type: ignore[no-any-return]
  File "/root/code/ai_based_education/run_app.py", line 135, in produe_growth_advice
    res = get_report(req)
  File "/root/code/ai_based_education/gen_report_wo_db.py", line 84, in get_report
    target_plan.pop('AÊ°£ÂçáÂ≠¶‰∏ªÁ∫ø')
KeyError: 'AÊ°£ÂçáÂ≠¶‰∏ªÁ∫ø'
 * Detected change in '/root/code/ai_based_education/test.py', reloading
input_check_result: True
ÂºÇÊ≠•Ë∞ÉÁî®Â§ßÊ®°ÂûãÂºÄÂßãÊó∂Èó¥ 2025-09-29 15:52:39
ÂºÇÊ≠•Ë∞ÉÁî®Â§ßÊ®°ÂûãÂºÄÂßãÊó∂Èó¥ 2025-09-29 15:52:39
ÂºÇÊ≠•Ë∞ÉÁî®Â§ßÊ®°ÂûãÂºÄÂßãÊó∂Èó¥ 2025-09-29 15:52:39
ÂºÇÊ≠•Ë∞ÉÁî®Â§ßÊ®°ÂûãÂºÄÂßãÊó∂Èó¥ 2025-09-29 15:52:39
ÂºÇÊ≠•Ë∞ÉÁî®Â§ßÊ®°ÂûãÁªìÊùüÊó∂Èó¥ 2025-09-29 15:52:43
ÂºÇÊ≠•Ë∞ÉÁî®Â§ßÊ®°ÂûãÁªìÊùüÊó∂Èó¥ 2025-09-29 15:52:43
ÂºÇÊ≠•Ë∞ÉÁî®Â§ßÊ®°ÂûãÁªìÊùüÊó∂Èó¥ 2025-09-29 15:52:43
ÂºÇÊ≠•Ë∞ÉÁî®Â§ßÊ®°ÂûãÁªìÊùüÊó∂Èó¥ 2025-09-29 15:52:45
**************: Â≠¶Ê†°Á±ªÂûã G12
input_check_result: False
eval_result [{'question_section_name': 'ÊàêÂ∞±Âä®Êú∫', 'question_type': 2, 'question': 'ËØ∑ÂàÜ‰∫´‰∏Ä‰ª∂ËÆ©Â≠©Â≠êÊúÄÊúâÊàêÂ∞±ÊÑüÁöÑ‰∫ãÊÉÖ„ÄÇ', 'answer': 'Ê≥ïÂõΩËÆΩÂæ∑ËØµ'}]
input_check_result: False
eval_result [{'question_section_name': 'Â≠©Â≠êÊú™Êù•ÊÑøÊôØ', 'question_type': 2, 'question': 'Â≠©Â≠êÊúâ‰ªÄ‰πàÊ¢¶ÊÉ≥ÂêóÔºü', 'answer': 'ÈÉΩÂ∏ÇÈ£éÂÖâ'}]
input_check_result: False
ÂºÇÊ≠•Ë∞ÉÁî®Â§ßÊ®°ÂûãÂºÄÂßãÊó∂Èó¥ 2025-09-29 15:57:55
ÂºÇÊ≠•Ë∞ÉÁî®Â§ßÊ®°ÂûãÂºÄÂßãÊó∂Èó¥ 2025-09-29 15:57:55
ÂºÇÊ≠•Ë∞ÉÁî®Â§ßÊ®°ÂûãÂºÄÂßãÊó∂Èó¥ 2025-09-29 15:57:55
ÂºÇÊ≠•Ë∞ÉÁî®Â§ßÊ®°ÂûãÂºÄÂßãÊó∂Èó¥ 2025-09-29 15:57:55
ÂºÇÊ≠•Ë∞ÉÁî®Â§ßÊ®°ÂûãÁªìÊùüÊó∂Èó¥ 2025-09-29 15:58:01
ÂºÇÊ≠•Ë∞ÉÁî®Â§ßÊ®°ÂûãÁªìÊùüÊó∂Èó¥ 2025-09-29 15:58:01
ÂºÇÊ≠•Ë∞ÉÁî®Â§ßÊ®°ÂûãÁªìÊùüÊó∂Èó¥ 2025-09-29 15:58:01
ÂºÇÊ≠•Ë∞ÉÁî®Â§ßÊ®°ÂûãÁªìÊùüÊó∂Èó¥ 2025-09-29 15:58:02
**************: ÁßÅÁ´ã G12
 * Restarting with stat
 * Debugger is active!
 * Debugger PIN: 995-271-986
 * Detected change in '/root/code/ai_based_education/test.py', reloading
 * Restarting with stat
 * Debugger is active!
 * Debugger PIN: 995-271-986
 * Detected change in '/root/code/ai_based_education/test.py', reloading
 * Restarting with stat
 * Debugger is active!
 * Debugger PIN: 995-271-986
127.0.0.1 - - [29/Sep/2025 16:05:04] "POST /swot HTTP/1.1" 200 -
87.120.191.33 - - [29/Sep/2025 16:08:15] "[33mGET / HTTP/1.1[0m" 404 -
116.232.217.248 - - [29/Sep/2025 16:15:54] "POST /swot HTTP/1.1" 200 -
116.232.217.248 - - [29/Sep/2025 16:16:30] "POST /swot HTTP/1.1" 200 -
116.232.217.248 - - [29/Sep/2025 16:22:19] "POST /growth_advice HTTP/1.1" 200 -
111.9.62.28 - - [29/Sep/2025 16:25:02] "[31m[1mPOST /growth_advice HTTP/1.1[0m" 400 -
116.232.217.248 - - [29/Sep/2025 16:28:30] "POST /growth_advice HTTP/1.1" 200 -
111.9.62.28 - - [29/Sep/2025 16:32:14] "[35m[1mPOST /growth_advice HTTP/1.1[0m" 500 -
Traceback (most recent call last):
  File "/usr/local/lib/python3.8/site-packages/flask/app.py", line 1498, in __call__
    return self.wsgi_app(environ, start_response)
  File "/usr/local/lib/python3.8/site-packages/flask/app.py", line 1476, in wsgi_app
    response = self.handle_exception(e)
  File "/usr/local/lib/python3.8/site-packages/flask/app.py", line 1473, in wsgi_app
    response = self.full_dispatch_request()
  File "/usr/local/lib/python3.8/site-packages/flask/app.py", line 882, in full_dispatch_request
    rv = self.handle_user_exception(e)
  File "/usr/local/lib/python3.8/site-packages/flask/app.py", line 880, in full_dispatch_request
    rv = self.dispatch_request()
  File "/usr/local/lib/python3.8/site-packages/flask/app.py", line 865, in dispatch_request
    return self.ensure_sync(self.view_functions[rule.endpoint])(**view_args)  # type: ignore[no-any-return]
  File "/root/code/ai_based_education/run_app.py", line 135, in produe_growth_advice
    res = get_report(req)
  File "/root/code/ai_based_education/gen_report_wo_db.py", line 69, in get_report
    basic_info['ÂßìÂêç'] = req['student_info']['name']
TypeError: list indices must be integers or slices, not str
111.9.62.28 - - [29/Sep/2025 16:33:31] "[35m[1mPOST /growth_advice HTTP/1.1[0m" 500 -
Traceback (most recent call last):
  File "/usr/local/lib/python3.8/site-packages/flask/app.py", line 1498, in __call__
    return self.wsgi_app(environ, start_response)
  File "/usr/local/lib/python3.8/site-packages/flask/app.py", line 1476, in wsgi_app
    response = self.handle_exception(e)
  File "/usr/local/lib/python3.8/site-packages/flask/app.py", line 1473, in wsgi_app
    response = self.full_dispatch_request()
  File "/usr/local/lib/python3.8/site-packages/flask/app.py", line 882, in full_dispatch_request
    rv = self.handle_user_exception(e)
  File "/usr/local/lib/python3.8/site-packages/flask/app.py", line 880, in full_dispatch_request
    rv = self.dispatch_request()
  File "/usr/local/lib/python3.8/site-packages/flask/app.py", line 865, in dispatch_request
    return self.ensure_sync(self.view_functions[rule.endpoint])(**view_args)  # type: ignore[no-any-return]
  File "/root/code/ai_based_education/run_app.py", line 135, in produe_growth_advice
    res = get_report(req)
  File "/root/code/ai_based_education/gen_report_wo_db.py", line 84, in get_report
    target_plan.pop('AÊ°£ÂçáÂ≠¶‰∏ªÁ∫ø')
KeyError: 'AÊ°£ÂçáÂ≠¶‰∏ªÁ∫ø'
111.9.62.28 - - [29/Sep/2025 16:33:38] "[35m[1mPOST /growth_advice HTTP/1.1[0m" 500 -
Traceback (most recent call last):
  File "/usr/local/lib/python3.8/site-packages/flask/app.py", line 1498, in __call__
    return self.wsgi_app(environ, start_response)
  File "/usr/local/lib/python3.8/site-packages/flask/app.py", line 1476, in wsgi_app
    response = self.handle_exception(e)
  File "/usr/local/lib/python3.8/site-packages/flask/app.py", line 1473, in wsgi_app
    response = self.full_dispatch_request()
  File "/usr/local/lib/python3.8/site-packages/flask/app.py", line 882, in full_dispatch_request
    rv = self.handle_user_exception(e)
  File "/usr/local/lib/python3.8/site-packages/flask/app.py", line 880, in full_dispatch_request
    rv = self.dispatch_request()
  File "/usr/local/lib/python3.8/site-packages/flask/app.py", line 865, in dispatch_request
    return self.ensure_sync(self.view_functions[rule.endpoint])(**view_args)  # type: ignore[no-any-return]
  File "/root/code/ai_based_education/run_app.py", line 135, in produe_growth_advice
    res = get_report(req)
  File "/root/code/ai_based_education/gen_report_wo_db.py", line 84, in get_report
    target_plan.pop('AÊ°£ÂçáÂ≠¶‰∏ªÁ∫ø')
KeyError: 'AÊ°£ÂçáÂ≠¶‰∏ªÁ∫ø'
116.232.217.248 - - [29/Sep/2025 16:34:18] "POST /growth_advice HTTP/1.1" 200 -
87.120.191.33 - - [29/Sep/2025 16:34:32] "[33mGET / HTTP/1.1[0m" 404 -
111.9.62.28 - - [29/Sep/2025 16:34:50] "[35m[1mPOST /growth_advice HTTP/1.1[0m" 500 -
Traceback (most recent call last):
  File "/usr/local/lib/python3.8/site-packages/flask/app.py", line 1498, in __call__
    return self.wsgi_app(environ, start_response)
  File "/usr/local/lib/python3.8/site-packages/flask/app.py", line 1476, in wsgi_app
    response = self.handle_exception(e)
  File "/usr/local/lib/python3.8/site-packages/flask/app.py", line 1473, in wsgi_app
    response = self.full_dispatch_request()
  File "/usr/local/lib/python3.8/site-packages/flask/app.py", line 882, in full_dispatch_request
    rv = self.handle_user_exception(e)
  File "/usr/local/lib/python3.8/site-packages/flask/app.py", line 880, in full_dispatch_request
    rv = self.dispatch_request()
  File "/usr/local/lib/python3.8/site-packages/flask/app.py", line 865, in dispatch_request
    return self.ensure_sync(self.view_functions[rule.endpoint])(**view_args)  # type: ignore[no-any-return]
  File "/root/code/ai_based_education/run_app.py", line 135, in produe_growth_advice
    res = get_report(req)
  File "/root/code/ai_based_education/gen_report_wo_db.py", line 84, in get_report
    target_plan.pop('AÊ°£ÂçáÂ≠¶‰∏ªÁ∫ø')
KeyError: 'AÊ°£ÂçáÂ≠¶‰∏ªÁ∫ø'
111.9.62.28 - - [29/Sep/2025 16:34:51] "[35m[1mPOST /growth_advice HTTP/1.1[0m" 500 -
Traceback (most recent call last):
  File "/usr/local/lib/python3.8/site-packages/flask/app.py", line 1498, in __call__
    return self.wsgi_app(environ, start_response)
  File "/usr/local/lib/python3.8/site-packages/flask/app.py", line 1476, in wsgi_app
    response = self.handle_exception(e)
  File "/usr/local/lib/python3.8/site-packages/flask/app.py", line 1473, in wsgi_app
    response = self.full_dispatch_request()
  File "/usr/local/lib/python3.8/site-packages/flask/app.py", line 882, in full_dispatch_request
    rv = self.handle_user_exception(e)
  File "/usr/local/lib/python3.8/site-packages/flask/app.py", line 880, in full_dispatch_request
    rv = self.dispatch_request()
  File "/usr/local/lib/python3.8/site-packages/flask/app.py", line 865, in dispatch_request
    return self.ensure_sync(self.view_functions[rule.endpoint])(**view_args)  # type: ignore[no-any-return]
  File "/root/code/ai_based_education/run_app.py", line 135, in produe_growth_advice
    res = get_report(req)
  File "/root/code/ai_based_education/gen_report_wo_db.py", line 84, in get_report
    target_plan.pop('AÊ°£ÂçáÂ≠¶‰∏ªÁ∫ø')
KeyError: 'AÊ°£ÂçáÂ≠¶‰∏ªÁ∫ø'
116.232.217.248 - - [29/Sep/2025 16:35:59] "[35m[1mPOST /growth_advice HTTP/1.1[0m" 500 -
Traceback (most recent call last):
  File "/usr/local/lib/python3.8/site-packages/flask/app.py", line 1498, in __call__
    return self.wsgi_app(environ, start_response)
  File "/usr/local/lib/python3.8/site-packages/flask/app.py", line 1476, in wsgi_app
    response = self.handle_exception(e)
  File "/usr/local/lib/python3.8/site-packages/flask/app.py", line 1473, in wsgi_app
    response = self.full_dispatch_request()
  File "/usr/local/lib/python3.8/site-packages/flask/app.py", line 882, in full_dispatch_request
    rv = self.handle_user_exception(e)
  File "/usr/local/lib/python3.8/site-packages/flask/app.py", line 880, in full_dispatch_request
    rv = self.dispatch_request()
  File "/usr/local/lib/python3.8/site-packages/flask/app.py", line 865, in dispatch_request
    return self.ensure_sync(self.view_functions[rule.endpoint])(**view_args)  # type: ignore[no-any-return]
  File "/root/code/ai_based_education/run_app.py", line 135, in produe_growth_advice
    res = get_report(req)
  File "/root/code/ai_based_education/gen_report_wo_db.py", line 84, in get_report
    target_plan.pop('AÊ°£ÂçáÂ≠¶‰∏ªÁ∫ø')
KeyError: 'AÊ°£ÂçáÂ≠¶‰∏ªÁ∫ø'
111.9.62.28 - - [29/Sep/2025 16:36:05] "[35m[1mPOST /growth_advice HTTP/1.1[0m" 500 -
